2025-02-09 18:36:50,800 - __main__ - ERROR - Database initialization failed: HTTPSConnectionPool(host='your_databricks_host', port=443): Max retries exceeded with url: /your_databricks_http_path (Caused by NameResolutionError("<urllib3.connection.HTTPSConnection object at 0x7fc3a8c145b0>: Failed to resolve 'your_databricks_host' ([Errno 8] nodename nor servname provided, or not known)"))
